<?xml version="1.0" ?>
<!-- =================================================================================== -->
<!-- |    This document was autogenerated by xacro from robotic_arm.xacro              | -->
<!-- |    EDITING THIS FILE BY HAND IS NOT RECOMMENDED                                 | -->
<!-- =================================================================================== -->
<robot name="robotic_arm">
  <material name="silver_default">
    <color rgba="0.700 0.700 0.700 1.000"/>
  </material>
  <material name="led_red">
    <color rgba="0.7686274509803922 0.20784313725490197 0.15294117647058825 1.0"/>
  </material>
  <material name="pa_12_nylon_pa_603cf_with_eos_p_3d_printers">
    <color rgba="0.24705882352941178 0.24705882352941178 0.24705882352941178 1.0"/>
  </material>
  <material name="oak">
    <color rgba="0.8157 0.6510 0.4902 1.0 "/>
  </material>
  <transmission name="base_waist_joint_tran">
    <type>transmission_interface/SimpleTransmission</type>
    <joint name="base_waist_joint">
      <hardwareInterface>hardware_interface/EffortJointInterface</hardwareInterface>
    </joint>
    <actuator name="base_waist_joint_actr">
      <hardwareInterface>hardware_interface/EffortJointInterface</hardwareInterface>
      <mechanicalReduction>1</mechanicalReduction>
    </actuator>
  </transmission>
  <transmission name="waist_link1_joint_tran">
    <type>transmission_interface/SimpleTransmission</type>
    <joint name="waist_link1_joint">
      <hardwareInterface>hardware_interface/EffortJointInterface</hardwareInterface>
    </joint>
    <actuator name="waist_link1_joint_actr">
      <hardwareInterface>hardware_interface/EffortJointInterface</hardwareInterface>
      <mechanicalReduction>1</mechanicalReduction>
    </actuator>
  </transmission>
  <transmission name="link1_link2_joint_tran">
    <type>transmission_interface/SimpleTransmission</type>
    <joint name="link1_link2_joint">
      <hardwareInterface>hardware_interface/EffortJointInterface</hardwareInterface>
    </joint>
    <actuator name="link1_link2_joint_actr">
      <hardwareInterface>hardware_interface/EffortJointInterface</hardwareInterface>
      <mechanicalReduction>1</mechanicalReduction>
    </actuator>
  </transmission>
  <transmission name="link2_gipper_base_joint_tran">
    <type>transmission_interface/SimpleTransmission</type>
    <joint name="link2_gipper_base_joint">
      <hardwareInterface>hardware_interface/EffortJointInterface</hardwareInterface>
    </joint>
    <actuator name="link2_gipper_base_joint_actr">
      <hardwareInterface>hardware_interface/EffortJointInterface</hardwareInterface>
      <mechanicalReduction>1</mechanicalReduction>
    </actuator>
  </transmission>
  <transmission name="right_gripper_joint_tran">
    <type>transmission_interface/SimpleTransmission</type>
    <joint name="right_gripper_joint">
      <hardwareInterface>hardware_interface/EffortJointInterface</hardwareInterface>
    </joint>
    <actuator name="right_gripper_joint_actr">
      <hardwareInterface>hardware_interface/EffortJointInterface</hardwareInterface>
      <mechanicalReduction>1</mechanicalReduction>
    </actuator>
  </transmission>
  <transmission name="left_gripper_joint_tran">
    <type>transmission_interface/SimpleTransmission</type>
    <joint name="left_gripper_joint">
      <hardwareInterface>hardware_interface/EffortJointInterface</hardwareInterface>
    </joint>
    <actuator name="left_gripper_joint_actr">
      <hardwareInterface>hardware_interface/EffortJointInterface</hardwareInterface>
      <mechanicalReduction>1</mechanicalReduction>
    </actuator>
  </transmission>
  <gazebo reference="base_link">
    <material>Gazebo/Wood</material>
    <mu1>0.2</mu1>
    <mu2>0.2</mu2>
    <self_collide>true</self_collide>
    <gravity>true</gravity>
  </gazebo>
  <gazebo reference="base">
    <material>Gazebo/FlatBlack</material>
    <mu1>0.2</mu1>
    <mu2>0.2</mu2>
    <self_collide>true</self_collide>
  </gazebo>
  <gazebo reference="waist">
    <material>Gazebo/FlatBlack</material>
    <mu1>0.2</mu1>
    <mu2>0.2</mu2>
    <self_collide>true</self_collide>
  </gazebo>
  <gazebo reference="link_1">
    <material>Gazebo/FlatBlack</material>
    <mu1>0.2</mu1>
    <mu2>0.2</mu2>
    <self_collide>true</self_collide>
  </gazebo>
  <gazebo reference="link_2">
    <material>Gazebo/FlatBlack</material>
    <mu1>0.2</mu1>
    <mu2>0.2</mu2>
    <self_collide>true</self_collide>
  </gazebo>
  <gazebo reference="gripper_base">
    <material>Gazebo/FlatBlack</material>
    <mu1>0.2</mu1>
    <mu2>0.2</mu2>
    <self_collide>true</self_collide>
  </gazebo>
  <gazebo reference="gripper_finger_1">
    <material>Gazebo/Blue</material>
    <mu1>0.2</mu1>
    <mu2>0.2</mu2>
    <self_collide>true</self_collide>
  </gazebo>
  <gazebo reference="gripper_finger_2">
    <material>Gazebo/Blue</material>
    <mu1>0.2</mu1>
    <mu2>0.2</mu2>
    <self_collide>true</self_collide>
  </gazebo>
  <gazebo reference="camera_support">
    <material>Gazebo/WoodFloor</material>
    <mu1>0.2</mu1>
    <mu2>0.2</mu2>
    <self_collide>true</self_collide>
  </gazebo>
  <gazebo reference="container_cubes">
    <material>Gazebo/Red</material>
    <mu1>0.2</mu1>
    <mu2>0.2</mu2>
    <self_collide>true</self_collide>
  </gazebo>
  <gazebo reference="container_cylinders">
    <material>Gazebo/Red</material>
    <mu1>0.2</mu1>
    <mu2>0.2</mu2>
    <self_collide>true</self_collide>
  </gazebo>
  <gazebo reference="container_hexagons">
    <material>Gazebo/Red</material>
    <mu1>0.2</mu1>
    <mu2>0.2</mu2>
    <self_collide>true</self_collide>
  </gazebo>
  <ros2_control name="RoboticArmSystem" type="system">
    <hardware>
      <plugin>gazebo_ros2_control/GazeboSystem</plugin>
    </hardware>
    <!-- Interfaces -->
    <joint name="base_waist_joint">
      <command_interface name="position">
        <param name="min">-1.570795</param>
        <param name="max">1.570795</param>
      </command_interface>
      <state_interface name="position"/>
    </joint>
    <joint name="waist_link1_joint">
      <command_interface name="position">
        <param name="min">-1.570795</param>
        <param name="max">1.570795</param>
      </command_interface>
      <state_interface name="position"/>
    </joint>
    <joint name="link1_link2_joint">
      <command_interface name="position">
        <param name="min">0,0</param>
        <param name="max">3.14159</param>
      </command_interface>
      <state_interface name="position"/>
    </joint>
    <joint name="link2_gripper_base_joint">
      <command_interface name="position">
        <param name="min">-1.570795</param>
        <param name="max">1.570795</param>
      </command_interface>
      <state_interface name="position"/>
    </joint>
    <joint name="right_gripper_joint">
      <command_interface name="position">
        <param name="min">0.0</param>
        <param name="max">0.7854</param>
      </command_interface>
      <state_interface name="position"/>
    </joint>
    <joint name="left_gripper_joint">
      <param name="mimic">right_gripper_joint</param>
      <param name="multiplier">-1</param>
      <command_interface name="position">
        <param name="min">-0.7854</param>
        <param name="max">0.0</param>
      </command_interface>
      <state_interface name="position"/>
    </joint>
  </ros2_control>
  <gazebo>
    <plugin filename="libgazebo_ros2_control.so" name="gazebo_ros2_control">
      <parameters>/home/newtonjeri/ai_based_sorting_robot_arm/install/robotic_arm_controllers/share/robotic_arm_controllers/config/robot_arm_controllers.yaml</parameters>
    </plugin>
  </gazebo>
  <!-- Links -->
  <link name="world"/>
  <link name="base_link">
    <inertial>
      <origin rpy="0 0 0" xyz="2.5964963671146073e-05 -0.12750519341019426 0.02735001860163422"/>
      <mass value="2.562361438794821"/>
      <inertia ixx="0.033829" ixy="-2e-06" ixz="-0.0" iyy="0.076749" iyz="0.0" izz="0.110468"/>
    </inertial>
    <visual>
      <origin rpy="0 0 0" xyz="0 0 0"/>
      <geometry>
        <mesh filename="package://robotic_arm_description/meshes/base_link.stl" scale="0.001 0.001 0.001"/>
      </geometry>
      <material name="oak"/>
    </visual>
    <collision>
      <origin rpy="0 0 0" xyz="0 0 0"/>
      <geometry>
        <mesh filename="package://robotic_arm_description/meshes/base_link.stl" scale="0.001 0.001 0.001"/>
      </geometry>
    </collision>
  </link>
  <link name="container_cubes">
    <inertial>
      <origin rpy="0 0 0" xyz="0.0021344768560282723 -1.5647124724599282e-05 0.026103286200414536"/>
      <mass value="0.8859344258495231"/>
      <inertia ixx="0.002047" ixy="1e-06" ixz="0.000223" iyy="0.003759" iyz="0.0" izz="0.004728"/>
    </inertial>
    <visual>
      <origin rpy="0 0 0" xyz="0.2025 0.225 -0.035"/>
      <geometry>
        <mesh filename="package://robotic_arm_description/meshes/container_cubes.stl" scale="0.001 0.001 0.001"/>
      </geometry>
      <material name="led_red"/>
    </visual>
    <collision>
      <origin rpy="0 0 0" xyz="0.2025 0.225 -0.035"/>
      <geometry>
        <mesh filename="package://robotic_arm_description/meshes/container_cubes.stl" scale="0.001 0.001 0.001"/>
      </geometry>
    </collision>
  </link>
  <link name="container_cylinders">
    <inertial>
      <origin rpy="0 0 0" xyz="-1.565155782010108e-05 -0.0021344802460424653 0.026103286200414424"/>
      <mass value="0.8859344258495231"/>
      <inertia ixx="0.003759" ixy="-1e-06" ixz="0.0" iyy="0.002047" iyz="-0.000223" izz="0.004728"/>
    </inertial>
    <visual>
      <origin rpy="0 0 0" xyz="0.2425 0.02 -0.035"/>
      <geometry>
        <mesh filename="package://robotic_arm_description/meshes/container_cylinders.stl" scale="0.001 0.001 0.001"/>
      </geometry>
      <material name="led_red"/>
    </visual>
    <collision>
      <origin rpy="0 0 0" xyz="0.2425 0.02 -0.035"/>
      <geometry>
        <mesh filename="package://robotic_arm_description/meshes/container_cylinders.stl" scale="0.001 0.001 0.001"/>
      </geometry>
    </collision>
  </link>
  <link name="container_hexagons">
    <inertial>
      <origin rpy="0 0 0" xyz="-1.565155782010108e-05 -0.0021344802460424445 0.0261032862004145"/>
      <mass value="0.8859344258495231"/>
      <inertia ixx="0.003759" ixy="-1e-06" ixz="0.0" iyy="0.002047" iyz="-0.000223" izz="0.004728"/>
    </inertial>
    <visual>
      <origin rpy="0 0 0" xyz="0.1375 0.02 -0.035"/>
      <geometry>
        <mesh filename="package://robotic_arm_description/meshes/container_hexagons.stl" scale="0.001 0.001 0.001"/>
      </geometry>
      <material name="led_red"/>
    </visual>
    <collision>
      <origin rpy="0 0 0" xyz="0.1375 0.02 -0.035"/>
      <geometry>
        <mesh filename="package://robotic_arm_description/meshes/container_hexagons.stl" scale="0.001 0.001 0.001"/>
      </geometry>
    </collision>
  </link>
  <link name="camera_support">
    <inertial>
      <origin rpy="0 0 0" xyz="8.696769445861888e-16 -0.01380572988450951 0.19182498575975282"/>
      <mass value="1.9073849170892592"/>
      <inertia ixx="0.059599" ixy="-0.0" ixz="0.0" iyy="0.059727" iyz="0.000448" izz="0.000405"/>
    </inertial>
    <visual>
      <origin rpy="0 0 0" xyz="-0.0 0.325 -0.02"/>
      <geometry>
        <mesh filename="package://robotic_arm_description/meshes/camera_support.stl" scale="0.001 0.001 0.001"/>
      </geometry>
      <material name="pa_12_nylon_pa_603cf_with_eos_p_3d_printers"/>
    </visual>
    <collision>
      <origin rpy="0 0 0" xyz="-0.0 0.325 -0.02"/>
      <geometry>
        <mesh filename="package://robotic_arm_description/meshes/camera_support.stl" scale="0.001 0.001 0.001"/>
      </geometry>
    </collision>
  </link>
  <link name="base">
    <inertial>
      <origin rpy="0 0 0" xyz="6.051376774735407e-07 -0.08000032966587473 0.05136562059426733"/>
      <mass value="0.5102582987586253"/>
      <inertia ixx="0.00162" ixy="-0.0" ixz="0.0" iyy="0.001541" iyz="-0.0" izz="0.002267"/>
    </inertial>
    <visual>
      <origin rpy="0 0 0" xyz="-0.0 -0.07 -0.035"/>
      <geometry>
        <mesh filename="package://robotic_arm_description/meshes/base.stl" scale="0.001 0.001 0.001"/>
      </geometry>
      <material name="pa_12_nylon_pa_603cf_with_eos_p_3d_printers"/>
    </visual>
    <collision>
      <origin rpy="0 0 0" xyz="-0.0 -0.07 -0.035"/>
      <geometry>
        <mesh filename="package://robotic_arm_description/meshes/base.stl" scale="0.001 0.001 0.001"/>
      </geometry>
    </collision>
  </link>
  <link name="waist">
    <inertial>
      <origin rpy="0 0 0" xyz="-0.013899791072812993 -0.0032841190361416073 0.023721429685911427"/>
      <mass value="0.11734363935702768"/>
      <inertia ixx="8.6e-05" ixy="-3e-06" ixz="1.4e-05" iyy="7.9e-05" iyz="1.1e-05" izz="8.5e-05"/>
    </inertial>
    <visual>
      <origin rpy="0 0 0" xyz="0.0 0.01 -0.121"/>
      <geometry>
        <mesh filename="package://robotic_arm_description/meshes/waist.stl" scale="0.001 0.001 0.001"/>
      </geometry>
      <material name="pa_12_nylon_pa_603cf_with_eos_p_3d_printers"/>
    </visual>
    <collision>
      <origin rpy="0 0 0" xyz="0.0 0.01 -0.121"/>
      <geometry>
        <mesh filename="package://robotic_arm_description/meshes/waist.stl" scale="0.001 0.001 0.001"/>
      </geometry>
    </collision>
  </link>
  <link name="link_1">
    <inertial>
      <origin rpy="0 0 0" xyz="0.007817729878360883 -4.041924911227235e-07 0.06000021649587681"/>
      <mass value="0.07112302510728019"/>
      <inertia ixx="0.000121" ixy="0.0" ixz="0.0" iyy="0.000116" iyz="-0.0" izz="1e-05"/>
    </inertial>
    <visual>
      <origin rpy="0 0 0" xyz="0.001 0.024069 -0.161262"/>
      <geometry>
        <mesh filename="package://robotic_arm_description/meshes/link_1.stl" scale="0.001 0.001 0.001"/>
      </geometry>
      <material name="pa_12_nylon_pa_603cf_with_eos_p_3d_printers"/>
    </visual>
    <collision>
      <origin rpy="0 0 0" xyz="0.001 0.024069 -0.161262"/>
      <geometry>
        <mesh filename="package://robotic_arm_description/meshes/link_1.stl" scale="0.001 0.001 0.001"/>
      </geometry>
    </collision>
  </link>
  <link name="link_2">
    <inertial>
      <origin rpy="0 0 0" xyz="-0.015945401802956827 -0.04619383654620061 4.672518474435616e-05"/>
      <mass value="0.11456681455688399"/>
      <inertia ixx="0.000224" ixy="2.7e-05" ixz="-0.0" iyy="2.7e-05" iyz="0.0" izz="0.00023"/>
    </inertial>
    <visual>
      <origin rpy="0 0 0" xyz="0.001 0.024069 -0.281262"/>
      <geometry>
        <mesh filename="package://robotic_arm_description/meshes/link_2.stl" scale="0.001 0.001 0.001"/>
      </geometry>
      <material name="pa_12_nylon_pa_603cf_with_eos_p_3d_printers"/>
    </visual>
    <collision>
      <origin rpy="0 0 0" xyz="0.001 0.024069 -0.281262"/>
      <geometry>
        <mesh filename="package://robotic_arm_description/meshes/link_2.stl" scale="0.001 0.001 0.001"/>
      </geometry>
    </collision>
  </link>


  <link name="gripper_base">
    <inertial>
      <origin rpy="0 0 0" xyz="0.016989765812987632 -0.030975366550403616 0.004301084726513138"/>
      <mass value="0.02850874527831614"/>
      <inertia ixx="1e-05" ixy="3e-06" ixz="1e-06" iyy="7e-06" iyz="1e-06" izz="1.4e-05"/>
    </inertial>
    <visual>
      <origin rpy="0 0 0" xyz="-0.00285 0.141419 -0.281562"/>
      <geometry>
        
        <box size="0.01 0.1 0.01"/>
        <!-- <mesh filename="package://robotic_arm_description/meshes/gripper_base.stl" scale="0.001 0.001 0.001"/> -->
      </geometry>
      <material name="led_red"/>
    </visual>
    <collision>
      <origin rpy="0 0 0" xyz="-0.00285 0.141419 -0.281562"/>
      <geometry>

        <box size="0.01 0.1 0.01"/>
        <!-- <mesh filename="package://robotic_arm_description/meshes/gripper_base.stl" scale="0.001 0.001 0.001"/> -->
      </geometry>
    </collision>
  </link>

  <link name = "end_effector">
  </link>

<!-- 
  <link name="gripper_finger_1">
    <inertial>
      <origin rpy="0 0 0" xyz="0.0025925452739234515 -0.04003700713978928 0.0020003926156425544"/>
      <mass value="0.00844478254120791"/>
      <inertia ixx="7e-06" ixy="1e-06" ixz="0.0" iyy="0.0" iyz="-0.0" izz="8e-06"/>
    </inertial>
    <visual>
      <origin rpy="0 0 0" xyz="-0.02875 0.179419 -0.295562"/>
      <geometry>
        <mesh filename="package://robotic_arm_description/meshes/gripper_finger_1.stl" scale="0.001 0.001 0.001"/>
      </geometry>
      <material name="pa_12_nylon_pa_603cf_with_eos_p_3d_printers"/>
    </visual>
    <collision>
      <origin rpy="0 0 0" xyz="-0.02875 0.179419 -0.295562"/>
      <geometry>
        <mesh filename="package://robotic_arm_description/meshes/gripper_finger_1.stl" scale="0.001 0.001 0.001"/>
      </geometry>
    </collision>
  </link>


  <link name="gripper_finger_2">
    <inertial>
      <origin rpy="0 0 0" xyz="-0.002592545273924804 -0.04003700713978928 0.002000392615642499"/>
      <mass value="0.00844478254120791"/>
      <inertia ixx="7e-06" ixy="-1e-06" ixz="-0.0" iyy="0.0" iyz="-0.0" izz="8e-06"/>
    </inertial>
    <visual>
      <origin rpy="0 0 0" xyz="-0.00185 0.179419 -0.295562"/>
      <geometry>
        <mesh filename="package://robotic_arm_description/meshes/gripper_finger_2.stl" scale="0.001 0.001 0.001"/>
      </geometry>
      <material name="pa_12_nylon_pa_603cf_with_eos_p_3d_printers"/>
    </visual>
    <collision>
      <origin rpy="0 0 0" xyz="-0.00185 0.179419 -0.295562"/>
      <geometry>
        <mesh filename="package://robotic_arm_description/meshes/gripper_finger_2.stl" scale="0.001 0.001 0.001"/>
      </geometry>
    </collision>
  </link> -->


  <!-- Joints -->
  <joint name="virtual_joint" type="fixed">
    <parent link="world"/>
    <child link="base_link"/>
  </joint>
  <joint name="rigid_1" type="fixed">
    <origin rpy="0 0 0" xyz="0.0 0.07 0.035"/>
    <parent link="base_link"/>
    <child link="base"/>
  </joint>
  <joint name="rigid_2" type="fixed">
    <origin rpy="0 0 0" xyz="-0.2025 -0.225 0.035"/>
    <parent link="base_link"/>
    <child link="container_cubes"/>
  </joint>
  <joint name="rigid_3" type="fixed">
    <origin rpy="0 0 0" xyz="-0.2425 -0.02 0.035"/>
    <parent link="base_link"/>
    <child link="container_cylinders"/>
  </joint>
  <joint name="rigid_4" type="fixed">
    <origin rpy="0 0 0" xyz="-0.1375 -0.02 0.035"/>
    <parent link="base_link"/>
    <child link="container_hexagons"/>
  </joint>
  <joint name="rigid_5" type="fixed">
    <origin rpy="0 0 0" xyz="0.0 -0.325 0.02"/>
    <parent link="base_link"/>
    <child link="camera_support"/>
  </joint>
  <joint name="base_waist_joint" type="revolute">
    <origin rpy="0 0 0" xyz="-0.0 -0.08 0.086"/>
    <parent link="base"/>
    <child link="waist"/>
    <axis xyz="-0.0 -0.0 1.0"/>
    <limit effort="100" lower="-1.570796" upper="1.570796" velocity="100"/>
  </joint>
  <joint name="waist_link1_joint" type="revolute">
    <origin rpy="0 0 0" xyz="-0.001 -0.014069 0.040262"/>
    <parent link="waist"/>
    <child link="link_1"/>
    <axis xyz="1.0 0.0 -0.0"/>
    <limit effort="100" lower="-1.570796" upper="1.570796" velocity="100"/>
  </joint>
  <joint name="link1_link2_joint" type="revolute">
    <origin rpy="0 0 0" xyz="0.0 0.0 0.12"/>
    <parent link="link_1"/>
    <child link="link_2"/>
    <axis xyz="1.0 -0.0 -0.0"/>
    <limit effort="100" lower="-1.570796" upper="1.570796" velocity="100"/>
  </joint>
  <joint name="link2_gripper_base_joint" type="revolute">
    <origin rpy="0 0 0" xyz="0.00385 -0.11735 0.0003"/>
    <parent link="link_2"/>
    <child link="gripper_base"/>
    <axis xyz="1.0 -0.0 0.0"/>
    <limit effort="100" lower="-1.570796" upper="1.570796" velocity="100"/>
  </joint>

  <joint name = "end_effector_link" type="fixed">
    <origin rpy="0 0 0" xyz=" 0.01 -0.1 0.01 "/>
    <parent link="gripper_base"/>
    <child link="end_effector"/>
  </joint>
  


  <!-- <joint name="right_gripper_joint" type="revolute">
    <origin rpy="0 0 0" xyz="0.0259 -0.038 0.014"/>
    <parent link="gripper_base"/>
    <child link="gripper_finger_1"/>
    <axis xyz="-0.0 0.0 1.0"/>
    <limit effort="100" lower="0.0" upper="1.047198" velocity="100"/>
  </joint>
  <joint name="left_gripper_joint" type="revolute">
    <origin rpy="0 0 0" xyz="-0.001 -0.038 0.014"/>
    <parent link="gripper_base"/>
    <child link="gripper_finger_2"/>
    <axis xyz="-0.0 0.0 1.0"/>
    <dynamics damping="10.0" friction="2.0"/>
    <limit effort="100" lower="-1.047198" upper="0.0" velocity="100"/>
    <mimic joint="right_gripper_joint" multiplier="-1"/>
  </joint> -->

</robot>
