<?xml version="1.0" encoding = "UTF-8"?>
<robot name="robotic_arm" xmlns:xacro="http://www.ros.org/wiki/xacro">

<!-- Load Simulated or Real Hardware Interfaces -->
<xacro:arg name="sim_mode" default="true"/>

<!-- Include materials properties to be used with rviz -->
<xacro:include filename="$(find robotic_arm_description)/urdf/materials.xacro" />

<xacro:include filename="$(find robotic_arm_description)/urdf/robotic_arm.trans" />
<!-- Include material properties to be used in gazebo -->
<xacro:include filename="$(find robotic_arm_description)/urdf/robotic_arm_gazebo.xacro"/>

<!-- Include ros2_control plugin-->
<xacro:include filename="$(find robotic_arm_description)/urdf/robotic_arm_ros2_control.xacro"/>

<!-- Include camera plugins -->
<xacro:include filename="$(find robotic_arm_description)/urdf/robotic_arm_camera.xacro"/>

<!-- Links -->
<link name = "world"/>

<!--include aruco marke-->
<xacro:include filename="$(find robotic_arm_description)/urdf/aruco_marker.xacro"/>

<!-- Properties -->
<xacro:property name="PI" value="3.147"/>


<link name="base_link">
  <inertial>
    <origin xyz="2.5964963671146073e-05 -0.12750519341019426 0.02735001860163422" rpy="0 0 0"/>
    <mass value="2.562361438794821"/>
    <inertia ixx="0.033829" iyy="0.076749" izz="0.110468" ixy="-2e-06" iyz="0.0" ixz="-0.0"/>
  </inertial>
  <visual>
    <origin xyz="0 0 0" rpy="0 0 0"/>
    <geometry>
      <mesh filename="package://robotic_arm_description/meshes/base_link.stl" scale="0.001 0.001 0.001"/>
    </geometry>
    <material name="oak"/>
  </visual>
  <collision>
    <origin xyz="0 0 0" rpy="0 0 0"/>
    <geometry>
      <mesh filename="package://robotic_arm_description/meshes/base_link.stl" scale="0.001 0.001 0.001"/>
    </geometry>
  </collision>
</link>

<link name="container_cubes">
  <inertial>
    <origin xyz="0.0021344768560282723 -1.5647124724599282e-05 0.026103286200414536" rpy="0 0 0"/>
    <mass value="0.8859344258495231"/>
    <inertia ixx="0.002047" iyy="0.003759" izz="0.004728" ixy="1e-06" iyz="0.0" ixz="0.000223"/>
  </inertial>
  <visual>
    <origin xyz="0.2025 0.225 -0.035" rpy="0 0 0"/>
    <geometry>
      <mesh filename="package://robotic_arm_description/meshes/container_cubes.stl" scale="0.001 0.001 0.001"/>
    </geometry>
    <material name="led_red"/>
  </visual>
  <collision>
    <origin xyz="0.2025 0.225 -0.035" rpy="0 0 0"/>
    <geometry>
      <mesh filename="package://robotic_arm_description/meshes/container_cubes.stl" scale="0.001 0.001 0.001"/>
    </geometry>
  </collision>
</link>

<link name="container_cylinders">
  <inertial>
    <origin xyz="-1.565155782010108e-05 -0.0021344802460424653 0.026103286200414424" rpy="0 0 0"/>
    <mass value="0.8859344258495231"/>
    <inertia ixx="0.003759" iyy="0.002047" izz="0.004728" ixy="-1e-06" iyz="-0.000223" ixz="0.0"/>
  </inertial>
  <visual>
    <origin xyz="0.2425 0.02 -0.035" rpy="0 0 0"/>
    <geometry>
      <mesh filename="package://robotic_arm_description/meshes/container_cylinders.stl" scale="0.001 0.001 0.001"/>
    </geometry>
    <material name="led_red"/>
  </visual>
  <collision>
    <origin xyz="0.2425 0.02 -0.035" rpy="0 0 0"/>
    <geometry>
      <mesh filename="package://robotic_arm_description/meshes/container_cylinders.stl" scale="0.001 0.001 0.001"/>
    </geometry>
  </collision>
</link>

<link name="container_hexagons">
  <inertial>
    <origin xyz="-1.565155782010108e-05 -0.0021344802460424445 0.0261032862004145" rpy="0 0 0"/>
    <mass value="0.8859344258495231"/>
    <inertia ixx="0.003759" iyy="0.002047" izz="0.004728" ixy="-1e-06" iyz="-0.000223" ixz="0.0"/>
  </inertial>
  <visual>
    <origin xyz="0.1375 0.02 -0.035" rpy="0 0 0"/>
    <geometry>
      <mesh filename="package://robotic_arm_description/meshes/container_hexagons.stl" scale="0.001 0.001 0.001"/>
    </geometry>
    <material name="led_red"/>
  </visual>
  <collision>
    <origin xyz="0.1375 0.02 -0.035" rpy="0 0 0"/>
    <geometry>
      <mesh filename="package://robotic_arm_description/meshes/container_hexagons.stl" scale="0.001 0.001 0.001"/>
    </geometry>
  </collision>
</link>

<link name="camera_support">
  <inertial>
    <origin xyz="-0.018363826080468604 -0.008283937089531401 0.3065870557744901" rpy="0 0 0"/>
    <mass value="2.9385762719335418"/>
    <inertia ixx="0.133646" iyy="0.133692" izz="0.00521" ixy="0.001039" iyz="-0.006152" ixz="0.011452"/>
  </inertial>
  <visual>
    <origin xyz="-0.2675 0.32 -0.019" rpy="0 0 0"/>
    <geometry>
      <mesh filename="package://robotic_arm_description/meshes/camera_support.stl" scale="0.001 0.001 0.001"/>
    </geometry>
    <material name="black_3d_printed"/>
  </visual>
  <collision>
    <origin xyz="-0.2675 0.32 -0.019" rpy="0 0 0"/>
    <geometry>
      <mesh filename="package://robotic_arm_description/meshes/camera_support.stl" scale="0.001 0.001 0.001"/>
    </geometry>
  </collision>
</link>

<link name="camera_link">
  <inertial>
    <origin xyz="-2.682209454540896e-10 4.349266702619037e-07 -0.0009999921768903963" rpy="0 0 0"/>
    <mass value="0.006279999999999998"/>
    <inertia ixx="0.0" iyy="0.0" izz="0.0" ixy="0.0" iyz="0.0" ixz="-0.0"/>
  </inertial>
  <visual>
    <origin xyz="-0.2245 0.249302 -0.53399" rpy="0 0 0"/>
    <geometry>
      <mesh filename="package://robotic_arm_description/meshes/camera_link.stl" scale="0.001 0.001 0.001"/>
    </geometry>
    <material name="steel_satin"/>
  </visual>
  <collision>
    <origin xyz="-0.2245 0.249302 -0.53399" rpy="0 0 0"/>
    <geometry>
      <mesh filename="package://robotic_arm_description/meshes/camera_link.stl" scale="0.001 0.001 0.001"/>
    </geometry>
  </collision>
</link>

<link name="camera_link_frame">
</link>

<link name="base">
  <inertial>
    <origin xyz="6.051376774735407e-07 -0.08000032966587473 0.05136562059426733" rpy="0 0 0"/>
    <mass value="0.5102582987586253"/>
    <inertia ixx="0.00162" iyy="0.001541" izz="0.002267" ixy="-0.0" iyz="-0.0" ixz="0.0"/>
  </inertial>
  <visual>
    <origin xyz="-0.0 -0.07 -0.035" rpy="0 0 0"/>
    <geometry>
      <mesh filename="package://robotic_arm_description/meshes/base.stl" scale="0.001 0.001 0.001"/>
    </geometry>
    <material name="black_3d_printed"/>
  </visual>
  <collision>
    <origin xyz="-0.0 -0.07 -0.035" rpy="0 0 0"/>
    <geometry>
      <mesh filename="package://robotic_arm_description/meshes/base.stl" scale="0.001 0.001 0.001"/>
    </geometry>
  </collision>
</link>

<link name="waist">
  <inertial>
    <origin xyz="-0.013899791072812993 -0.0032841190361416073 0.023721429685911427" rpy="0 0 0"/>
    <mass value="0.11734363935702768"/>
    <inertia ixx="8.6e-05" iyy="7.9e-05" izz="8.5e-05" ixy="-3e-06" iyz="1.1e-05" ixz="1.4e-05"/>
  </inertial>
  <visual>
    <origin xyz="0.0 0.01 -0.121" rpy="0 0 0"/>
    <geometry>
      <mesh filename="package://robotic_arm_description/meshes/waist.stl" scale="0.001 0.001 0.001"/>
    </geometry>
    <material name="black_3d_printed"/>
  </visual>
  <collision>
    <origin xyz="0.0 0.01 -0.121" rpy="0 0 0"/>
    <geometry>
      <mesh filename="package://robotic_arm_description/meshes/waist.stl" scale="0.001 0.001 0.001"/>
    </geometry>
  </collision>
</link>

<link name="link_1">
  <inertial>
    <origin xyz="0.007817729878360883 -4.041924911227235e-07 0.06000021649587681" rpy="0 0 0"/>
    <mass value="0.07112302510728019"/>
    <inertia ixx="0.000121" iyy="0.000116" izz="1e-05" ixy="0.0" iyz="-0.0" ixz="0.0"/>
  </inertial>
  <visual>
    <origin xyz="0.001 0.024069 -0.161262" rpy="0 0 0"/>
    <geometry>
      <mesh filename="package://robotic_arm_description/meshes/link_1.stl" scale="0.001 0.001 0.001"/>
    </geometry>
    <material name="black_3d_printed"/>
  </visual>
  <collision>
    <origin xyz="0.001 0.024069 -0.161262" rpy="0 0 0"/>
    <geometry>
      <mesh filename="package://robotic_arm_description/meshes/link_1.stl" scale="0.001 0.001 0.001"/>
    </geometry>
  </collision>
</link>

<link name="link_2">
  <inertial>
    <origin xyz="-0.015945401802956827 -0.04619383654620061 4.672518474435616e-05" rpy="0 0 0"/>
    <mass value="0.11456681455688399"/>
    <inertia ixx="0.000224" iyy="2.7e-05" izz="0.00023" ixy="2.7e-05" iyz="0.0" ixz="-0.0"/>
  </inertial>
  <visual>
    <origin xyz="0.001 0.024069 -0.281262" rpy="0 0 0"/>
    <geometry>
      <mesh filename="package://robotic_arm_description/meshes/link_2.stl" scale="0.001 0.001 0.001"/>
    </geometry>
    <material name="black_3d_printed"/>
  </visual>
  <collision>
    <origin xyz="0.001 0.024069 -0.281262" rpy="0 0 0"/>
    <geometry>
      <mesh filename="package://robotic_arm_description/meshes/link_2.stl" scale="0.001 0.001 0.001"/>
    </geometry>
  </collision>
</link>

<link name="gripper_base">
  <inertial>
    <origin xyz="0.016989765812987632 -0.030975366550403616 0.004301084726513138" rpy="0 0 0"/>
    <mass value="0.02850874527831614"/>
    <inertia ixx="1e-05" iyy="7e-06" izz="1.4e-05" ixy="3e-06" iyz="1e-06" ixz="1e-06"/>
  </inertial>
  <visual>
    <origin xyz="-0.00285 0.141419 -0.281562" rpy="0 0 0"/>
    <geometry>
      <mesh filename="package://robotic_arm_description/meshes/gripper_base.stl" scale="0.001 0.001 0.001"/>
    </geometry>
    <material name="black_3d_printed"/>
  </visual>
  <collision>
    <origin xyz="-0.00285 0.141419 -0.281562" rpy="0 0 0"/>
    <geometry>
      <mesh filename="package://robotic_arm_description/meshes/gripper_base.stl" scale="0.001 0.001 0.001"/>
    </geometry>
  </collision>
</link>

<link name="gripper_finger_1">
  <inertial>
    <origin xyz="0.0025925452739234515 -0.04003700713978928 0.0020003926156425544" rpy="0 0 0"/>
    <mass value="0.00844478254120791"/>
    <inertia ixx="7e-06" iyy="0.0" izz="8e-06" ixy="1e-06" iyz="-0.0" ixz="0.0"/>
  </inertial>
  <visual>
    <origin xyz="-0.02875 0.179419 -0.295562" rpy="0 0 0"/>
    <geometry>
      <mesh filename="package://robotic_arm_description/meshes/gripper_finger_1.stl" scale="0.001 0.001 0.001"/>
    </geometry>
    <material name="black_3d_printed"/>
  </visual>
  <collision>
    <origin xyz="-0.02875 0.179419 -0.295562" rpy="0 0 0"/>
    <geometry>
      <mesh filename="package://robotic_arm_description/meshes/gripper_finger_1.stl" scale="0.001 0.001 0.001"/>
    </geometry>
  </collision>
</link>

<link name="gripper_finger_2">
  <inertial>
    <origin xyz="-0.002592545273924804 -0.04003700713978928 0.002000392615642499" rpy="0 0 0"/>
    <mass value="0.00844478254120791"/>
    <inertia ixx="7e-06" iyy="0.0" izz="8e-06" ixy="-1e-06" iyz="-0.0" ixz="-0.0"/>
  </inertial>
  <visual>
    <origin xyz="-0.00185 0.179419 -0.295562" rpy="0 0 0"/>
    <geometry>
      <mesh filename="package://robotic_arm_description/meshes/gripper_finger_2.stl" scale="0.001 0.001 0.001"/>
    </geometry>
    <material name="black_3d_printed"/>
  </visual>
  <collision>
    <origin xyz="-0.00185 0.179419 -0.295562" rpy="0 0 0"/>
    <geometry>
      <mesh filename="package://robotic_arm_description/meshes/gripper_finger_2.stl" scale="0.001 0.001 0.001"/>
    </geometry>
  </collision>
</link>


<!-- Joints -->

<joint name = "virtual_joint" type= "fixed">
  <parent link="world"/>
  <child link="base_link"/>
</joint>

<joint name="rigid_1" type="fixed">
  <origin xyz="0.0 0.07 0.035" rpy="0 0 0"/>
  <parent link="base_link"/>
  <child link="base"/>
</joint>

<joint name="rigid_2" type="fixed">
  <origin xyz="-0.2025 -0.225 0.035" rpy="0 0 0"/>
  <parent link="base_link"/>
  <child link="container_cubes"/>
</joint>

<joint name="rigid_3" type="fixed">
  <origin xyz="-0.2425 -0.02 0.035" rpy="0 0 0"/>
  <parent link="base_link"/>
  <child link="container_cylinders"/>
</joint>

<joint name="rigid_4" type="fixed">
  <origin xyz="-0.1375 -0.02 0.035" rpy="0 0 0"/>
  <parent link="base_link"/>
  <child link="container_hexagons"/>
</joint>

<joint name="rigid_5" type="fixed">
  <origin xyz="0.2375 -0.32 0.019" rpy="0 0 0"/>
  <parent link="base_link"/>
  <child link="camera_support"/>
</joint>

<joint name="camera_joint" type="fixed">
  <origin xyz="-0.043 0.070698 0.51499" rpy="0 0 0"/>
  <parent link="camera_support"/>
  <child link="camera_link"/>
</joint>

<joint name="camera_link_frame_joint" type="fixed">
  <origin xyz="0.0 0.0 0.0" rpy="${PI} ${PI/2} 0"/>
  <parent link="camera_link"/>
  <child link="camera_link_frame"/>
 
  
</joint>  

<joint name="base_waist_joint" type="revolute">
  <origin xyz="-0.0 -0.08 0.086" rpy="0 0 0"/>
  <parent link="base"/>
  <child link="waist"/>
  <axis xyz="-0.0 -0.0 1.0"/>
  <limit upper="1.570796" lower="-1.570796" effort="100" velocity="100"/>
</joint>

<joint name="waist_link1_joint" type="revolute">
  <origin xyz="-0.001 -0.014069 0.040262" rpy="0 0 0"/>
  <parent link="waist"/>
  <child link="link_1"/>
  <axis xyz="1.0 0.0 -0.0"/>
  <limit upper="1.570796" lower="-1.570796" effort="100" velocity="100"/>
</joint>

<joint name="link1_link2_joint" type="revolute">
  <origin xyz="0.0 0.0 0.12" rpy="0 0 0"/>
  <parent link="link_1"/>
  <child link="link_2"/>
  <axis xyz="1.0 -0.0 -0.0"/>
  <limit upper="1.570796" lower="-1.570796" effort="100" velocity="100"/>
</joint>

<joint name="link2_gripper_base_joint" type="revolute">
  <origin xyz="0.00385 -0.11735 0.0003" rpy="0 0 0"/>
  <parent link="link_2"/>
  <child link="gripper_base"/>
  <axis xyz="1.0 -0.0 0.0"/>
  <limit upper="1.570796" lower="-1.570796" effort="100" velocity="100"/>
</joint>


<joint name="right_gripper_joint" type="revolute">
  <origin xyz="0.0259 -0.038 0.014" rpy="0 0 0"/>
  <parent link="gripper_base"/>
  <child link="gripper_finger_1"/>
  <axis xyz="-0.0 0.0 1.0"/>
  <limit upper="1.047198" lower="0.0" effort="100" velocity="100"/>
</joint>

<joint name="left_gripper_joint" type="revolute">
  <origin xyz="-0.001 -0.038 0.014" rpy="0 0 0"/>
  <parent link="gripper_base"/>
  <child link="gripper_finger_2"/>
  <axis xyz="-0.0 0.0 1.0"/>
  <dynamics damping="10.0" friction="2.0"/>
  <limit upper="0.0" lower="-1.047198" effort="100" velocity="100"/>
  <mimic joint = "right_gripper_joint" multiplier = "-1"/>
</joint>


</robot>
