<?xml version="1.0" ?>
<!-- =================================================================================== -->
<!-- |    This document was autogenerated by xacro from robotic_arm.xacro              | -->
<!-- |    EDITING THIS FILE BY HAND IS NOT RECOMMENDED                                 | -->
<!-- =================================================================================== -->
<robot name="robotic_arm">
  <material name="silver">
    <color rgba="0.0 0.4 0.6 1.0"/>
  </material>
  <material name="black">
    <color rgba="0.0 0.0 0.0 1.0"/>
  </material>
  <material name="red">
    <color rgba="1.0 0.0 0.0 1.0"/>
  </material>
  <material name="blue">
    <color rgba="0.0 0.0 1.0 1.0"/>
  </material>
  <transmission name="joint_1_tran">
    <type>transmission_interface/SimpleTransmission</type>
    <joint name="joint_1">
      <hardwareInterface>hardware_interface/EffortJointInterface</hardwareInterface>
    </joint>
    <actuator name="joint_1_actr">
      <hardwareInterface>hardware_interface/EffortJointInterface</hardwareInterface>
      <mechanicalReduction>1</mechanicalReduction>
    </actuator>
  </transmission>
  <transmission name="joint_2_tran">
    <type>transmission_interface/SimpleTransmission</type>
    <joint name="joint_2">
      <hardwareInterface>hardware_interface/EffortJointInterface</hardwareInterface>
    </joint>
    <actuator name="joint_2_actr">
      <hardwareInterface>hardware_interface/EffortJointInterface</hardwareInterface>
      <mechanicalReduction>1</mechanicalReduction>
    </actuator>
  </transmission>
  <transmission name="joint_3_tran">
    <type>transmission_interface/SimpleTransmission</type>
    <joint name="joint_3">
      <hardwareInterface>hardware_interface/EffortJointInterface</hardwareInterface>
    </joint>
    <actuator name="joint_3_actr">
      <hardwareInterface>hardware_interface/EffortJointInterface</hardwareInterface>
      <mechanicalReduction>1</mechanicalReduction>
    </actuator>
  </transmission>
  <transmission name="joint_4_tran">
    <type>transmission_interface/SimpleTransmission</type>
    <joint name="joint_4">
      <hardwareInterface>hardware_interface/EffortJointInterface</hardwareInterface>
    </joint>
    <actuator name="joint_4_actr">
      <hardwareInterface>hardware_interface/EffortJointInterface</hardwareInterface>
      <mechanicalReduction>1</mechanicalReduction>
    </actuator>
  </transmission>
  <transmission name="Slider 7_tran">
    <type>transmission_interface/SimpleTransmission</type>
    <joint name="Slider 7">
      <hardwareInterface>hardware_interface/EffortJointInterface</hardwareInterface>
    </joint>
    <actuator name="Slider 7_actr">
      <hardwareInterface>hardware_interface/EffortJointInterface</hardwareInterface>
      <mechanicalReduction>1</mechanicalReduction>
    </actuator>
  </transmission>
  <transmission name="Slider 8_tran">
    <type>transmission_interface/SimpleTransmission</type>
    <joint name="Slider 8">
      <hardwareInterface>hardware_interface/EffortJointInterface</hardwareInterface>
    </joint>
    <actuator name="Slider 8_actr">
      <hardwareInterface>hardware_interface/EffortJointInterface</hardwareInterface>
      <mechanicalReduction>1</mechanicalReduction>
    </actuator>
  </transmission>
  <gazebo>
    <plugin filename="libgazebo_ros2_control.so" name="control"/>
  </gazebo>
  <gazebo reference="base_link">
    <material>Gazebo/DarkGrey</material>
    <mu1>0.2</mu1>
    <mu2>0.2</mu2>
    <self_collide>true</self_collide>
    <gravity>true</gravity>
  </gazebo>
  <gazebo reference="waist">
    <material>Gazebo/Wood</material>
    <mu1>0.2</mu1>
    <mu2>0.2</mu2>
    <self_collide>true</self_collide>
  </gazebo>
  <gazebo reference="link_1">
    <material>Gazebo/Wood</material>
    <mu1>0.2</mu1>
    <mu2>0.2</mu2>
    <self_collide>true</self_collide>
  </gazebo>
  <gazebo reference="link_2a">
    <material>Gazebo/Wood</material>
    <mu1>0.2</mu1>
    <mu2>0.2</mu2>
    <self_collide>true</self_collide>
  </gazebo>
  <gazebo reference="link_2b">
    <material>Gazebo/Wood</material>
    <mu1>0.2</mu1>
    <mu2>0.2</mu2>
    <self_collide>true</self_collide>
  </gazebo>
  <gazebo reference="gripper_base">
    <material>Gazebo/Wood</material>
    <mu1>0.2</mu1>
    <mu2>0.2</mu2>
    <self_collide>true</self_collide>
  </gazebo>
  <gazebo reference="camera_link">
    <material>Gazebo/FlatBlack</material>
    <mu1>0.2</mu1>
    <mu2>0.2</mu2>
    <self_collide>true</self_collide>
  </gazebo>
  <gazebo reference="servomotormicro9g_v2_1">
    <material>Gazebo/Black</material>
    <mu1>0.2</mu1>
    <mu2>0.2</mu2>
    <self_collide>true</self_collide>
  </gazebo>
  <gazebo reference="servomotormg996r_v2_1">
    <material>Gazebo/Black</material>
    <mu1>0.2</mu1>
    <mu2>0.2</mu2>
    <self_collide>true</self_collide>
  </gazebo>
  <gazebo reference="servomotormicro9g_v2_2">
    <material>Gazebo/Black</material>
    <mu1>0.2</mu1>
    <mu2>0.2</mu2>
    <self_collide>true</self_collide>
  </gazebo>
  <gazebo reference="servomotormg996r_v2_2">
    <material>Gazebo/Black</material>
    <mu1>0.2</mu1>
    <mu2>0.2</mu2>
    <self_collide>true</self_collide>
  </gazebo>
  <gazebo reference="slidder_gripper_1">
    <material>Gazebo/DarkGrey</material>
    <mu1>0.2</mu1>
    <mu2>0.2</mu2>
    <self_collide>true</self_collide>
  </gazebo>
  <gazebo reference="slidder_gripper_2">
    <material>Gazebo/DarkGrey</material>
    <mu1>0.2</mu1>
    <mu2>0.2</mu2>
    <self_collide>true</self_collide>
  </gazebo>
  <link name="world"/>
  <link name="base_link">
    <inertial>
      <origin rpy="0 0 0" xyz="-0.018665097932950923 0.008373602393624096 0.020061176615408474"/>
      <mass value="37.446846482870264"/>
      <inertia ixx="0.651431" ixy="0.176946" ixz="-0.038541" iyy="1.819145" iyz="0.025331" izz="2.242189"/>
    </inertial>
    <visual>
      <origin rpy="0 0 0" xyz="0 0 0"/>
      <geometry>
        <mesh filename="package://robotic_arm_description/meshes/base_link.stl" scale="0.001 0.001 0.001"/>
      </geometry>
    </visual>
    <collision>
      <origin rpy="0 0 0" xyz="0 0 0"/>
      <geometry>
        <mesh filename="package://robotic_arm_description/meshes/base_link.stl" scale="0.001 0.001 0.001"/>
      </geometry>
    </collision>
  </link>
  <link name="waist">
    <inertial>
      <origin rpy="0 0 0" xyz="-0.004325137554017311 -0.006085387024749173 0.019240916153630563"/>
      <mass value="0.571710754468902"/>
      <inertia ixx="0.000465" ixy="6.7e-05" ixz="-0.0" iyy="0.000451" iyz="7.2e-05" izz="0.000465"/>
    </inertial>
    <visual>
      <origin rpy="0 0 0" xyz="0.27 -0.13 -0.101"/>
      <geometry>
        <mesh filename="package://robotic_arm_description/meshes/waist.stl" scale="0.001 0.001 0.001"/>
      </geometry>
      <material name="black"/>
    </visual>
    <collision>
      <origin rpy="0 0 0" xyz="0.27 -0.13 -0.101"/>
      <geometry>
        <mesh filename="package://robotic_arm_description/meshes/waist.stl" scale="0.001 0.001 0.001"/>
      </geometry>
    </collision>
  </link>
  <link name="link_1">
    <inertial>
      <origin rpy="0 0 0" xyz="0.03932970912597472 -0.0304951563107842 0.034414880490293676"/>
      <mass value="0.5075597700837723"/>
      <inertia ixx="0.000611" ixy="0.000272" ixz="-0.000242" iyy="0.000576" iyz="0.000258" izz="0.000579"/>
    </inertial>
    <visual>
      <origin rpy="0 0 0" xyz="0.2634 -0.117119 -0.14128"/>
      <geometry>
        <mesh filename="package://robotic_arm_description/meshes/link_1.stl" scale="0.001 0.001 0.001"/>
      </geometry>
      <material name="red"/>
    </visual>
    <collision>
      <origin rpy="0 0 0" xyz="0.2634 -0.117119 -0.14128"/>
      <geometry>
        <mesh filename="package://robotic_arm_description/meshes/link_1.stl" scale="0.001 0.001 0.001"/>
      </geometry>
    </collision>
  </link>
  <link name="link_2a">
    <inertial>
      <origin rpy="0 0 0" xyz="0.021760779101838823 -0.031526656195889166 -0.017698174049491033"/>
      <mass value="0.368736609571802"/>
      <inertia ixx="0.000284" ixy="0.000149" ixz="8.8e-05" iyy="0.00027" iyz="-9.2e-05" izz="0.000341"/>
    </inertial>
    <visual>
      <origin rpy="0 0 0" xyz="0.196144 -0.045431 -0.210109"/>
      <geometry>
        <mesh filename="package://robotic_arm_description/meshes/link_2a.stl" scale="0.001 0.001 0.001"/>
      </geometry>
      <material name="black"/>
    </visual>
    <collision>
      <origin rpy="0 0 0" xyz="0.196144 -0.045431 -0.210109"/>
      <geometry>
        <mesh filename="package://robotic_arm_description/meshes/link_2a.stl" scale="0.001 0.001 0.001"/>
      </geometry>
    </collision>
  </link>
  <link name="link_2b">
    <inertial>
      <origin rpy="0 0 0" xyz="0.0046871934926014935 -0.01758526636949733 -0.007526666944419946"/>
      <mass value="0.12768227270402752"/>
      <inertia ixx="2.7e-05" ixy="9e-06" ixz="4e-06" iyy="3.4e-05" iyz="-2e-06" izz="2.8e-05"/>
    </inertial>
    <visual>
      <origin rpy="0 0 0" xyz="0.134655 0.008416 -0.172179"/>
      <geometry>
        <mesh filename="package://robotic_arm_description/meshes/link_2b.stl" scale="0.001 0.001 0.001"/>
      </geometry>
      <material name="black"/>
    </visual>
    <collision>
      <origin rpy="0 0 0" xyz="0.134655 0.008416 -0.172179"/>
      <geometry>
        <mesh filename="package://robotic_arm_description/meshes/link_2b.stl" scale="0.001 0.001 0.001"/>
      </geometry>
    </collision>
  </link>
  <link name="gripper_base">
    <inertial>
      <origin rpy="0 0 0" xyz="0.027529630324851395 -0.01204235810533322 0.00914814783980572"/>
      <mass value="0.14749809489819876"/>
      <inertia ixx="3.6e-05" ixy="1.7e-05" ixz="-1.3e-05" iyy="5.9e-05" iyz="8e-06" izz="7.8e-05"/>
    </inertial>
    <visual>
      <origin rpy="0 0 0" xyz="0.117292 0.026923 -0.160346"/>
      <geometry>
        <mesh filename="package://robotic_arm_description/meshes/gripper_base.stl" scale="0.001 0.001 0.001"/>
      </geometry>
      <material name="silver"/>
    </visual>
    <collision>
      <origin rpy="0 0 0" xyz="0.117292 0.026923 -0.160346"/>
      <geometry>
        <mesh filename="package://robotic_arm_description/meshes/gripper_base.stl" scale="0.001 0.001 0.001"/>
      </geometry>
    </collision>
  </link>
  <link name="slider_slot">
    <inertial>
      <origin rpy="0 0 0" xyz="0.0013722494188505852 -0.001463236933399198 0.0001750716067638325"/>
      <mass value="0.004356750035092236"/>
      <inertia ixx="0.0" ixy="-0.0" ixz="0.0" iyy="0.0" iyz="-0.0" izz="0.0"/>
    </inertial>
    <visual>
      <origin rpy="0 0 0" xyz="0.066181 0.063863 -0.17555"/>
      <geometry>
        <mesh filename="package://robotic_arm_description/meshes/slider_slot.stl" scale="0.001 0.001 0.001"/>
      </geometry>
      <material name="silver"/>
    </visual>
    <collision>
      <origin rpy="0 0 0" xyz="0.066181 0.063863 -0.17555"/>
      <geometry>
        <mesh filename="package://robotic_arm_description/meshes/slider_slot.stl" scale="0.001 0.001 0.001"/>
      </geometry>
    </collision>
  </link>
  <link name="slidder_gripper_1">
    <inertial>
      <origin rpy="0 0 0" xyz="0.020937593705417333 -0.013012654159922518 0.0020833272549800885"/>
      <mass value="0.017151155514247545"/>
      <inertia ixx="2e-06" ixy="2e-06" ixz="-0.0" iyy="2e-06" iyz="0.0" izz="4e-06"/>
    </inertial>
    <visual>
      <origin rpy="0 0 0" xyz="0.076439 0.074853 -0.175637"/>
      <geometry>
        <mesh filename="package://robotic_arm_description/meshes/slidder_gripper_1.stl" scale="0.001 0.001 0.001"/>
      </geometry>
      <material name="motor_color">
        <color rgba="0.0 0.0 0.0 1.0"/>
      </material>
    </visual>
    <collision>
      <origin rpy="0 0 0" xyz="0.076439 0.074853 -0.175637"/>
      <geometry>
        <mesh filename="package://robotic_arm_description/meshes/slidder_gripper_1.stl" scale="0.001 0.001 0.001"/>
      </geometry>
    </collision>
  </link>
  <link name="slidder_gripper_2">
    <inertial>
      <origin rpy="0 0 0" xyz="0.011651774683778773 -0.021723927124737863 0.0020833272549800608"/>
      <mass value="0.017151155514247545"/>
      <inertia ixx="2e-06" ixy="2e-06" ixz="-0.0" iyy="2e-06" iyz="0.0" izz="4e-06"/>
    </inertial>
    <visual>
      <origin rpy="0 0 0" xyz="0.05456 0.054327 -0.175637"/>
      <geometry>
        <mesh filename="package://robotic_arm_description/meshes/slidder_gripper_2.stl" scale="0.001 0.001 0.001"/>
      </geometry>
      <material name="">
        <color rgba="0.0 0.0 0.0 1.0"/>
      </material>
    </visual>
    <collision>
      <origin rpy="0 0 0" xyz="0.05456 0.054327 -0.175637"/>
      <geometry>
        <mesh filename="package://robotic_arm_description/meshes/slidder_gripper_2.stl" scale="0.001 0.001 0.001"/>
      </geometry>
    </collision>
  </link>
  <link name="camera_link">
    <inertial>
      <origin rpy="0 0 0" xyz="-0.01000000000000012 0.009999999999999981 -0.0024999999999999467"/>
      <mass value="0.015699999999999995"/>
      <inertia ixx="1e-06" ixy="0.0" ixz="0.0" iyy="1e-06" iyz="-0.0" izz="1e-06"/>
    </inertial>
    <visual>
      <origin rpy="0 0 0" xyz="-0.3425 0.1925 -0.615"/>
      <geometry>
        <mesh filename="package://robotic_arm_description/meshes/camera_link.stl" scale="0.001 0.001 0.001"/>
      </geometry>
      <material name="blue"/>
    </visual>
    <collision>
      <origin rpy="0 0 0" xyz="-0.3425 0.1925 -0.615"/>
      <geometry>
        <mesh filename="package://robotic_arm_description/meshes/camera_link.stl" scale="0.001 0.001 0.001"/>
      </geometry>
    </collision>
  </link>
  <link name="servomotormicro9g_v2_1">
    <inertial>
      <origin rpy="0 0 0" xyz="0.004246784236529702 0.002300076771489329 -0.01403736470537334"/>
      <mass value="0.05595068017526718"/>
      <inertia ixx="4e-06" ixy="-1e-06" ixz="0.0" iyy="5e-06" iyz="0.0" izz="3e-06"/>
    </inertial>
    <visual>
      <origin rpy="0 0 0" xyz="0.073248 0.036015 -0.17611"/>
      <geometry>
        <mesh filename="package://robotic_arm_description/meshes/servomotormicro9g_v2_1.stl" scale="0.001 0.001 0.001"/>
      </geometry>
      <material name="blue"/>
    </visual>
    <collision>
      <origin rpy="0 0 0" xyz="0.073248 0.036015 -0.17611"/>
      <geometry>
        <mesh filename="package://robotic_arm_description/meshes/servomotormicro9g_v2_1.stl" scale="0.001 0.001 0.001"/>
      </geometry>
    </collision>
  </link>
  <link name="servomotormicro9g_v2_2">
    <inertial>
      <origin rpy="0 0 0" xyz="-0.013173285358933598 -0.0065534501953197245 0.0019739894599794805"/>
      <mass value="0.05595068017526718"/>
      <inertia ixx="3e-06" ixy="-0.0" ixz="1e-06" iyy="4e-06" iyz="-0.0" izz="5e-06"/>
    </inertial>
    <visual>
      <origin rpy="0 0 0" xyz="0.118386 0.02795 -0.160346"/>
      <geometry>
        <mesh filename="package://robotic_arm_description/meshes/servomotormicro9g_v2_2.stl" scale="0.001 0.001 0.001"/>
      </geometry>
      <material name="blue"/>
    </visual>
    <collision>
      <origin rpy="0 0 0" xyz="0.118386 0.02795 -0.160346"/>
      <geometry>
        <mesh filename="package://robotic_arm_description/meshes/servomotormicro9g_v2_2.stl" scale="0.001 0.001 0.001"/>
      </geometry>
    </collision>
  </link>
  <link name="servomotormg996r_v2_1">
    <inertial>
      <origin rpy="0 0 0" xyz="-0.023970472531686826 0.010854967398329491 0.005821878031642358"/>
      <mass value="0.2658706317147462"/>
      <inertia ixx="5.1e-05" ixy="-2e-06" ixz="7e-06" iyy="4.7e-05" iyz="-9e-06" izz="7e-05"/>
    </inertial>
    <visual>
      <origin rpy="0 0 0" xyz="0.181171 -0.013395 -0.199955"/>
      <geometry>
        <mesh filename="package://robotic_arm_description/meshes/servomotormg996r_v2_1.stl" scale="0.001 0.001 0.001"/>
      </geometry>
      <material name="blue"/>
    </visual>
    <collision>
      <origin rpy="0 0 0" xyz="0.181171 -0.013395 -0.199955"/>
      <geometry>
        <mesh filename="package://robotic_arm_description/meshes/servomotormg996r_v2_1.stl" scale="0.001 0.001 0.001"/>
      </geometry>
    </collision>
  </link>
  <link name="servomotormg996r_v2_2">
    <inertial>
      <origin rpy="0 0 0" xyz="-0.002373320488633479 -0.02181114979206003 0.014282327800950845"/>
      <mass value="0.2658706317147462"/>
      <inertia ixx="5.2e-05" ixy="-7e-06" ixz="-1.1e-05" iyy="5.6e-05" iyz="1e-05" izz="6.1e-05"/>
    </inertial>
    <visual>
      <origin rpy="0 0 0" xyz="0.288487 -0.123397 -0.119537"/>
      <geometry>
        <mesh filename="package://robotic_arm_description/meshes/servomotormg996r_v2_2.stl" scale="0.001 0.001 0.001"/>
      </geometry>
      <material name="blue"/>
    </visual>
    <collision>
      <origin rpy="0 0 0" xyz="0.288487 -0.123397 -0.119537"/>
      <geometry>
        <mesh filename="package://robotic_arm_description/meshes/servomotormg996r_v2_2.stl" scale="0.001 0.001 0.001"/>
      </geometry>
    </collision>
  </link>
  <joint name="fixed" type="fixed">
    <parent link="world"/>
    <child link="base_link"/>
  </joint>
  <joint name="joint_1" type="revolute">
    <origin rpy="0 0 0" xyz="-0.27 0.13 0.101"/>
    <parent link="base_link"/>
    <child link="waist"/>
    <dynamics dumping="10.0" friction="2.0"/>
    <axis xyz="0.0 0.0 1.0"/>
    <limit effort="100" lower="-1.570796" upper="1.570796" velocity="100"/>
  </joint>
  <joint name="joint_2" type="revolute">
    <origin rpy="0 0 0" xyz="0.0066 -0.012881 0.04028"/>
    <parent link="waist"/>
    <child link="link_1"/>
    <dynamics dumping="10.0" friction="2.0"/>
    <axis xyz="-0.729288 -0.684207 0.0"/>
    <limit effort="100" lower="-1.570796" upper="1.570796" velocity="100"/>
  </joint>
  <joint name="joint_3" type="revolute">
    <origin rpy="0 0 0" xyz="0.067256 -0.071688 0.068829"/>
    <parent link="link_1"/>
    <child link="link_2a"/>
    <dynamics dumping="10.0" friction="2.0"/>
    <axis xyz="0.729288 0.684207 -0.0"/>
    <limit effort="100" lower="-1.570796" upper="1.570796" velocity="100"/>
  </joint>
  <joint name="Rigid 4" type="fixed">
    <origin rpy="0 0 0" xyz="0.061489 -0.053847 -0.03793"/>
    <parent link="link_2a"/>
    <child link="link_2b"/>
  </joint>
  <joint name="joint_4" type="revolute">
    <origin rpy="0 0 0" xyz="0.017363 -0.018507 -0.011833"/>
    <parent link="link_2b"/>
    <child link="gripper_base"/>
    <dynamics dumping="10.0" friction="2.0"/>
    <axis xyz="-0.729288 -0.684207 0.0"/>
    <limit effort="100" lower="-1.570796" upper="1.570796" velocity="100"/>
  </joint>
  <joint name="Rigid 6" type="fixed">
    <origin rpy="0 0 0" xyz="0.051111 -0.03694 0.015204"/>
    <parent link="gripper_base"/>
    <child link="slider_slot"/>
  </joint>
  <joint name="left_gripper_finger_joint" type="prismatic">
    <origin rpy="0 0 0" xyz="-0.010258 -0.01099 8.7e-05"/>
    <parent link="slider_slot"/>
    <child link="slidder_gripper_1"/>
    <dynamics dumping="10.0" friction="2.0"/>
    <axis xyz="-0.729288 -0.684207 0.0"/>
    <limit effort="100" lower="-0.008" upper="0.0" velocity="100"/>
  </joint>
  <joint name="right_gripper_finger_joint" type="prismatic">
    <origin rpy="0 0 0" xyz="0.011621 0.009536 8.7e-05"/>
    <parent link="slider_slot"/>
    <child link="slidder_gripper_2"/>
    <dynamics dumping="10.0" friction="2.0"/>
    <axis xyz="0.729288 0.684207 -0.0"/>
    <limit effort="100" lower="-0.008" upper="0.0" velocity="100"/>
  </joint>
  <joint name="Rigid 9" type="fixed">
    <origin rpy="0 0 0" xyz="0.3425 -0.1925 0.615"/>
    <parent link="base_link"/>
    <child link="camera_link"/>
  </joint>
  <joint name="Rigid 10" type="fixed">
    <origin rpy="0 0 0" xyz="0.044044 -0.009092 0.015764"/>
    <parent link="gripper_base"/>
    <child link="servomotormicro9g_v2_1"/>
  </joint>
  <joint name="Rigid 11" type="fixed">
    <origin rpy="0 0 0" xyz="0.016269 -0.019534 -0.011833"/>
    <parent link="link_2b"/>
    <child link="servomotormicro9g_v2_2"/>
  </joint>
  <joint name="Rigid 12" type="fixed">
    <origin rpy="0 0 0" xyz="0.014973 -0.032036 -0.010154"/>
    <parent link="link_2a"/>
    <child link="servomotormg996r_v2_1"/>
  </joint>
  <joint name="Rigid 13" type="fixed">
    <origin rpy="0 0 0" xyz="-0.018487 -0.006603 0.018537"/>
    <parent link="waist"/>
    <child link="servomotormg996r_v2_2"/>
  </joint>
  <!-- Gazebo Plugin -->
  <gazebo>
    <plugin filename="libgazebo_ros2_control.so" name="gazebo_ros2_control">
      <robot_param>robot_description</robot_param>
      <robot_param_node>robot_state_publisher</robot_param_node>
      <parameters>/home/newtonjeri/ai_based_sorting_robot_arm/src/robotic_arm_bringup/config/controller_configuration.yaml</parameters>
    </plugin>
  </gazebo>
  <!-- Ros2 Control -->
  <ros2_control name="GazeboSystem" type="system">
    <hardware>
      <plugin>gazebo_ros2_control/GazeboSystem</plugin>
    </hardware>
    <joint name="joint_1">
      <command_interface name="position">
        <param name="min">-3.14</param>
        <param name="max">3.14</param>
      </command_interface>
      <command_interface name="velocity">
        <param name="min">-3.15</param>
        <param name="max">3.15</param>
      </command_interface>
      <state_interface name="position"/>
      <state_interface name="velocity"/>
      <state_interface name="effort"/>
      <param name="initial_position">0.0</param>
    </joint>
    <joint name="joint_2">
      <command_interface name="position">
        <param name="min">-3.14</param>
        <param name="max">3.14</param>
      </command_interface>
      <command_interface name="velocity">
        <param name="min">-3.15</param>
        <param name="max">3.15</param>
      </command_interface>
      <state_interface name="position"/>
      <state_interface name="velocity"/>
      <state_interface name="effort"/>
      <param name="initial_position">-1.57</param>
    </joint>
    <joint name="joint_3">
      <command_interface name="position">
        <param name="min">-3.14</param>
        <param name="max">3.14</param>
      </command_interface>
      <command_interface name="velocity">
        <param name="min">-3.15</param>
        <param name="max">3.15</param>
      </command_interface>
      <state_interface name="position"/>
      <state_interface name="velocity"/>
      <state_interface name="effort"/>
      <param name="initial_position">0.0</param>
    </joint>
    <joint name="joint_4">
      <command_interface name="position">
        <param name="min">-3.14</param>
        <param name="max">3.14</param>
      </command_interface>
      <command_interface name="velocity">
        <param name="min">-3.2</param>
        <param name="max">3.2</param>
      </command_interface>
      <state_interface name="position"/>
      <state_interface name="velocity"/>
      <state_interface name="effort"/>
      <param name="initial_position">-1.57</param>
    </joint>
    <joint name="left_gripper_finger_joint">
      <command_interface name="position">
        <param name="min">-0.008</param>
        <param name="max">0.0</param>
      </command_interface>
      <command_interface name="velocity">
        <param name="min">-0.01</param>
        <param name="max">0.1</param>
      </command_interface>
      <state_interface name="position"/>
      <state_interface name="velocity"/>
      <state_interface name="effort"/>
      <param name="initial_position">-0.008</param>
    </joint>
    <joint name="right_gripper_finger_joint">
      <command_interface name="position">
        <param name="min">-0.008</param>
        <param name="max">0.0</param>
      </command_interface>
      <command_interface name="velocity">
        <param name="min">-0.01</param>
        <param name="max">0.1</param>
      </command_interface>
      <state_interface name="position"/>
      <state_interface name="velocity"/>
      <state_interface name="effort"/>
      <param name="initial_position">-0.008</param>
    </joint>
  </ros2_control>
</robot>
